<?xml version="1.0" ?>
<robot name="snake_robot" >


  <material name="blue">
    <color rgba="0.3765 0.5647 0.101 1"/>
  </material>

  <material name="gray">
    <color rgba="0.0 0.0 0.0 1"/>
  </material>
<!--
  <box size="0.5 0.1 0.1">
-->
  <link name="base_link">
    <inertial>
      <origin xyz=" 0 0 0" rpy="90 0 0" />
      <mass value="1.0"/>
      <inertia ixx="0.1" ixy="0.0" ixz="0.0" iyy="0.1" iyz="0.0" izz="0.1"/>
    </inertial>
    <visual>
      <geometry>
        <box size="0.1 0.1 0.5"/>
      </geometry>
      <material name="blue"/>
    </visual>
    <collision>
      <geometry>
        <box size="0.1 0.1 0.5"/>
      </geometry>
    </collision>

  <gazebo reference="base_link">
    <material>Gazebo/Blue</material>
  </gazebo>
  </link>

  <link name="link2">
    <visual>
      <geometry>
        <box size="0.1 0.1 0.5"/>
      </geometry>
      <origin xyz=" 0 0 0.25" rpy = "0 0 0" />
      <material name="gray"/>
    </visual>
    <inertial>
      <origin xyz=" 0 0 0" rpy="0 0 0" />
      <mass value="1.0"/>
      <inertia ixx="0.1" ixy="0.0" ixz="0.0" iyy="0.1" iyz="0.0" izz="0.1"/>
    </inertial>
    <collision>
      <geometry>
        <box size="0.1 0.1 0.5"/>
      </geometry>
    </collision>

  <gazebo reference="link2">
    <material>Gazebo/Green</material>
  </gazebo>
  </link>

  <link name="link3">
    <visual>
      <geometry>
        <box size="0.1 0.1 0.5"/>
      </geometry>
      <material name="blue"/>
      <origin xyz=" 0 0 0.25" rpy = "0 0 0" />
    </visual>
    <inertial>
      <origin xyz=" 0 0 0" rpy="0 0 0" />
      <mass value="1.0"/>
      <inertia ixx="0.1" ixy="0.0" ixz="0.0" iyy="0.1" iyz="0.0" izz="0.1"/>
    </inertial>
    <collision>
      <geometry>
        <box size="0.1 0.1 0.5"/>
      </geometry>
    </collision>
  </link>

  <link name="link4">
    <visual>
      <geometry>
        <box size="0.1 0.1 0.5"/>
      </geometry>
    <material name="gray"/>
    <origin xyz=" 0 0 0.25" rpy = "0 0 0" />
    </visual>
    <inertial>
      <origin xyz=" 0 0 0" rpy="0 0 0" />
      <mass value="1.0"/>
      <inertia ixx="0.1" ixy="0.0" ixz="0.0" iyy="0.1" iyz="0.0" izz="0.1"/>
    </inertial>
    <collision>
      <geometry>
        <box size="0.1 0.1 0.5"/>
      </geometry>
    </collision>
  </link>

  <link name="link5">
    <visual>
      <geometry>
        <box size="0.1 0.1 0.5"/>
      </geometry>
      <material name="blue"/>
      <origin xyz=" 0 0 0.25" rpy = "0 0 0" />
    </visual>
    <inertial>
      <origin xyz=" 0 0 0" rpy="0 0 0" />
      <mass value="1.0"/>
      <inertia ixx="0.1" ixy="0.0" ixz="0.0" iyy="0.1" iyz="0.0" izz="0.1"/>
    </inertial>
    <collision>
      <geometry>
        <box size="0.1 0.1 0.5"/>
      </geometry>
    </collision>
  </link>

    <link name="link6">
    <visual>
      <geometry>
        <box size="0.1 0.1 0.5"/>
      </geometry>
      <material name="gray"/>
      <origin xyz=" 0 0 0.25" rpy = "0 0 0" />
    </visual>
    <inertial>
      <origin xyz=" 0 0 0" rpy="0 0 0" />
      <mass value="1.0"/>
      <inertia ixx="0.1" ixy="0.0" ixz="0.0" iyy="0.1" iyz="0.0" izz="0.1"/>
    </inertial>
    <collision>
      <geometry>
        <box size="0.1 0.1 0.5"/>
      </geometry>
    </collision>
  </link>

  <link name="link7">
    <visual>
      <geometry>
        <box size="0.1 0.1 0.5"/>
      </geometry>
      <material name="blue"/>
      <origin xyz=" 0 0 0.25" rpy = "0 0 0" />
    </visual>
    <inertial>
      <origin xyz=" 0 0 0" rpy="0 0 0" />
      <mass value="1.0"/>
      <inertia ixx="0.1" ixy="0.0" ixz="0.0" iyy="0.1" iyz="0.0" izz="0.1"/>
    </inertial>
    <collision>
      <geometry>
        <box size="0.1 0.1 0.5"/>
      </geometry>
    </collision>
  </link>

  <link name="link8">
    <visual>
      <geometry>
        <box size="0.1 0.1 0.5"/>
      </geometry>
      <material name="gray"/>
      <origin xyz=" 0 0 0.25" rpy = "0 0 0" />
    </visual>
    <inertial>
      <origin xyz=" 0 0 0" rpy="0 0 0" />
      <mass value="1.0"/>
      <inertia ixx="0.1" ixy="0.0" ixz="0.0" iyy="0.1" iyz="0.0" izz="0.1"/>
    </inertial>
    <collision>
      <geometry>
        <box size="0.1 0.1 0.5"/>
      </geometry>
    </collision>
  </link>
  
  <link name="link9">
    <visual>
      <geometry>
        <box size="0.1 0.1 0.5"/>
      </geometry>
      <material name="blue"/>
      <origin xyz=" 0 0 0.25" rpy = "0 0 0" />
    </visual>
    <inertial>
      <origin xyz=" 0 0 0" rpy="0 0 0" />
      <mass value="1.0"/>
      <inertia ixx="0.1" ixy="0.0" ixz="0.0" iyy="0.1" iyz="0.0" izz="0.1"/>
    </inertial>
    <collision>
      <geometry>
        <box size="0.1 0.1 0.5"/>
      </geometry>
    </collision>
  </link>

  <link name="link10">
    <visual>
      <geometry>
        <box size="0.1 0.1 0.5"/>
      </geometry>
      <material name="gray"/>
      <origin xyz=" 0 0 0.25" rpy = "0 0 0" />
    </visual>
    <inertial>
      <origin xyz=" 0 0 0" rpy="0 0 0" />
      <mass value="1.0"/>
      <inertia ixx="0.1" ixy="0.0" ixz="0.0" iyy="0.1" iyz="0.0" izz="0.1"/>
    </inertial>
    <collision>
      <geometry>
        <box size="0.1 0.1 0.5"/>
      </geometry>
    </collision>
  </link>

  <link name="link11">
    <visual>
      <geometry>
        <box size="0.1 0.1 0.5"/>
      </geometry>
      <material name="blue"/>
      <origin xyz=" 0 0 0.25" rpy = "0 0 0" />
    </visual>
    <inertial>
      <origin xyz=" 0 0 0" rpy="0 0 0" />
      <mass value="1.0"/>
      <inertia ixx="0.1" ixy="0.0" ixz="0.0" iyy="0.1" iyz="0.0" izz="0.1"/>
    </inertial>
    <collision>
      <geometry>
        <box size="0.1 0.1 0.5"/>
      </geometry>
    </collision>
  </link>

    <link name="link12">
    <visual>
      <geometry>
        <box size="0.1 0.1 0.5"/>
      </geometry>
      <material name="gray"/>
      <origin xyz=" 0 0 0.25" rpy = "0 0 0" />
    </visual>
    <inertial>
      <origin xyz=" 0 0 0" rpy="0 0 0" />
      <mass value="1.0"/>
      <inertia ixx="0.1" ixy="0.0" ixz="0.0" iyy="0.1" iyz="0.0" izz="0.1"/>
    </inertial>
    <collision>
      <geometry>
        <box size="0.1 0.1 0.5"/>
      </geometry>
    </collision>
  </link>

  <link name="link13">
    <visual>
      <geometry>
        <box size="0.1 0.1 0.5"/>
      </geometry>
      <material name="blue"/>
      <origin xyz=" 0 0 0.25" rpy = "0 0 0" />
    </visual>
    <inertial>
      <origin xyz=" 0 0 0" rpy="0 0 0" />
      <mass value="1.0"/>
      <inertia ixx="0.1" ixy="0.0" ixz="0.0" iyy="0.1" iyz="0.0" izz="0.1"/>
    </inertial>
    <collision>
      <geometry>
        <box size="0.1 0.1 0.5"/>
      </geometry>
    </collision>
  </link>
  
  <link name="link14">
    <visual>
      <geometry>
        <box size="0.1 0.1 0.5"/>
      </geometry>
      <material name="gray"/>
      <origin xyz=" 0 0 0.25" rpy = "0 0 0" />
    </visual>
    <inertial>
      <origin xyz=" 0 0 0" rpy="0 0 0" />
      <mass value="1.0"/>
      <inertia ixx="0.1" ixy="0.0" ixz="0.0" iyy="0.1" iyz="0.0" izz="0.1"/>
    </inertial>
    <collision>
      <geometry>
        <box size="0.1 0.1 0.5"/>
      </geometry>
    </collision>
  </link>

  <link name="link15">
    <visual>
      <geometry>
        <box size="0.1 0.1 0.5"/>
      </geometry>
      <material name="blue"/>
      <origin xyz=" 0 0 0.25" rpy = "0 0 0" />
    </visual>
    <inertial>
      <origin xyz=" 0 0 0" rpy="0 0 0" />
      <mass value="1.0"/>
      <inertia ixx="0.1" ixy="0.0" ixz="0.0" iyy="0.1" iyz="0.0" izz="0.1"/>
    </inertial>
    <collision>
      <geometry>
        <box size="0.1 0.1 0.5"/>
      </geometry>
    </collision>
  </link>

  <link name="link16">
    <visual>
      <geometry>
        <box size="0.1 0.1 0.5"/>
      </geometry>
      <material name="gray"/>
      <origin xyz=" 0 0 0.25" rpy = "0 0 0" />
    </visual>
    <inertial>
      <origin xyz=" 0 0 0" rpy="0 0 0" />
      <mass value="1.0"/>
      <inertia ixx="0.1" ixy="0.0" ixz="0.0" iyy="0.1" iyz="0.0" izz="0.1"/>
    </inertial>
    <collision>
      <geometry>
        <box size="0.1 0.1 0.5"/>
      </geometry>
    </collision>
  </link>


  <joint name="joint1" type="continuous" >
    <gazebo reference="joint1">
  		<implicitSpringDamper>True</implicitSpringDamper>
	</gazebo>
    <parent link="base_link"/>
    <child link="link2"/>
    <origin xyz=" 0 0 0.25" rpy = "0 0 0" />
    <axis xyz="1 0 0" />
  </joint>

  <joint name="joint2" type="continuous">
    <gazebo reference="joint2">
  		<implicitSpringDamper>True</implicitSpringDamper>
	</gazebo>
    <parent link="link2"/>
    <child link="link3"/>
    <origin xyz=" 0 0 0.5" rpy = "0 0 0" />
    <axis xyz="0 1 0" />
  </joint>

  <joint name="joint3" type="continuous" >
    <gazebo reference="joint3">
  		<implicitSpringDamper>True</implicitSpringDamper>
	</gazebo>
    <parent link="link3"/>
    <child link="link4"/>
    <origin xyz=" 0 0 0.5" rpy = "0 0 0" />
    <axis xyz="1 0 0" />
  </joint>
  
  <joint name="joint4" type="continuous">
    <gazebo reference="joint4">
  		<implicitSpringDamper>True</implicitSpringDamper>
	</gazebo>
    <parent link="link4"/>
    <child link="link5"/>
    <origin xyz=" 0 0 0.5" rpy = "0 0 0" />
    <axis xyz="0 1 0" />
  </joint>
  
  <joint name="joint5" type="continuous" >
  	<gazebo reference="joint5">
  		<implicitSpringDamper>True</implicitSpringDamper>
	</gazebo>
    <parent link="link5"/>
    <child link="link6"/>
    <origin xyz=" 0 0 0.5" rpy = "0 0 0" />
    <axis xyz="1 0 0" />
  </joint>

  <joint name="joint6" type="continuous" >
    <gazebo reference="joint6">
  		<implicitSpringDamper>True</implicitSpringDamper>
	</gazebo>
    <parent link="link6"/>
    <child link="link7"/>
    <origin xyz=" 0 0 0.5" rpy = "0 0 0" />
    <axis xyz="0 1 0" />
  </joint>
  
  <joint name="joint7" type="continuous"  >
  	<gazebo reference="joint7">
  		<implicitSpringDamper>True</implicitSpringDamper>
	</gazebo>
    <parent link="link7"/>
    <child link="link8"/>
    <origin xyz=" 0 0 0.5" rpy = "0 0 0" />
    <axis xyz="1 0 0" />
  </joint>

  <joint name="joint8" type="continuous" >
  	<gazebo reference="joint8">
  		<implicitSpringDamper>True</implicitSpringDamper>
	</gazebo>
    <parent link="link8"/>
    <child link="link9"/>
    <origin xyz=" 0 0 0.5" rpy = "0 0 0" />
    <axis xyz="0 1 0" />
  </joint>

  <joint name="joint9" type="continuous" >
  	<gazebo reference="joint9">
  		<implicitSpringDamper>True</implicitSpringDamper>
	</gazebo>
    <parent link="link9"/>
    <child link="link10"/>
    <origin xyz=" 0 0 0.5" rpy = "0 0 0" />
    <axis xyz="1 0 0" />
  </joint>

  <joint name="joint10" type="continuous" >
    <gazebo reference="joint9">
      <implicitSpringDamper>True</implicitSpringDamper>
  </gazebo>
    <parent link="link10"/>
    <child link="link11"/>
    <origin xyz=" 0 0 0.5" rpy = "0 0 0" />
    <axis xyz="0 1 0" />
  </joint>

    <joint name="joint11" type="continuous" >
    <gazebo reference="joint11">
      <implicitSpringDamper>True</implicitSpringDamper>
  </gazebo>
    <parent link="link11"/>
    <child link="link12"/>
    <origin xyz=" 0 0 0.5" rpy = "0 0 0" />
    <axis xyz="1 0 0" />
  </joint>
  
  <joint name="joint12" type="continuous"  >
    <gazebo reference="joint12">
      <implicitSpringDamper>True</implicitSpringDamper>
  </gazebo>
    <parent link="link12"/>
    <child link="link13"/>
    <origin xyz=" 0 0 0.5" rpy = "0 0 0" />
    <axis xyz="0 1 0" />
  </joint>

  <joint name="joint13" type="continuous" >
    <gazebo reference="joint13">
      <implicitSpringDamper>True</implicitSpringDamper>
  </gazebo>
    <parent link="link13"/>
    <child link="link14"/>
    <origin xyz=" 0 0 0.5" rpy = "0 0 0" />
    <axis xyz="1 0 0" />
  </joint>

  <joint name="joint14" type="continuous" >
    <gazebo reference="joint14">
      <implicitSpringDamper>True</implicitSpringDamper>
  </gazebo>
    <parent link="link14"/>
    <child link="link15"/>
    <origin xyz=" 0 0 0.5" rpy = "0 0 0" />
    <axis xyz="0 1 0" />
  </joint>

  <joint name="joint15" type="continuous" >
    <gazebo reference="joint15">
      <implicitSpringDamper>True</implicitSpringDamper>
  </gazebo>
    <parent link="link15"/>
    <child link="link16"/>
    <origin xyz=" 0 0 0.5" rpy = "0 0 0" />
    <axis xyz="1 0 0" />
  </joint>




 <!--  NOW WE INCLUDE CONTROLS FOR ROS -->

  <gazebo>
    <plugin name="gazebo_ros_control" filename="libgazebo_ros_control.so">
      <robotNamespace>/snake_robot</robotNamespace>
    </plugin>
  </gazebo> 

  <transmission name="base_to_second_trans">
    <type>transmission_interface/SimpleTransmission</type>
    <actuator name="motor1">
      <mechanicalReduction>100</mechanicalReduction>
    </actuator>
    <joint name="joint1">
      <hardwareInterface>EffortJointInterface</hardwareInterface>
    </joint>
  </transmission>

  <transmission name="second_to_third_trans">
    <type>transmission_interface/SimpleTransmission</type>
    <actuator name="motor2">
      <mechanicalReduction>100</mechanicalReduction>
    </actuator>
    <joint name="joint2">
      <hardwareInterface>EffortJointInterface</hardwareInterface>
    </joint>
  </transmission>



  <transmission name="third_to_fourth_trans">
    <type>transmission_interface/SimpleTransmission</type>
    <actuator name="motor3">
      <mechanicalReduction>100</mechanicalReduction>
    </actuator>
    <joint name="joint3">
      <hardwareInterface>EffortJointInterface</hardwareInterface>
    </joint>
  </transmission>

  <transmission name="fourth_to_fifth_trans">
    <type>transmission_interface/SimpleTransmission</type>
    <actuator name="motor4">
      <mechanicalReduction>100</mechanicalReduction>
    </actuator>
    <joint name="joint4">
      <hardwareInterface>EffortJointInterface</hardwareInterface>
    </joint>
  </transmission>

  <transmission name="fifth_to_sixth_trans">
    <type>transmission_interface/SimpleTransmission</type>
    <actuator name="motor5">
      <mechanicalReduction>100</mechanicalReduction>
    </actuator>
    <joint name="joint5">
      <hardwareInterface>EffortJointInterface</hardwareInterface>
    </joint>
  </transmission>
  
  <transmission name="sixth_to_seventh_trans">
    <type>transmission_interface/SimpleTransmission</type>
    <actuator name="motor6">
      <mechanicalReduction>100</mechanicalReduction>
    </actuator>
    <joint name="joint6">
      <hardwareInterface>EffortJointInterface</hardwareInterface>
    </joint>
  </transmission>


  <transmission name="seventh_to_eight_trans">
    <type>transmission_interface/SimpleTransmission</type>
    <actuator name="motor7">
      <mechanicalReduction>100</mechanicalReduction>
    </actuator>
    <joint name="joint7">
      <hardwareInterface>EffortJointInterface</hardwareInterface>
    </joint>
  </transmission>

  <transmission name="eigth_to_nineth_trans">
    <type>transmission_interface/SimpleTransmission</type>
    <actuator name="motor8">
      <mechanicalReduction>100</mechanicalReduction>
    </actuator>
    <joint name="joint8">
      <hardwareInterface>EffortJointInterface</hardwareInterface>
    </joint>
  </transmission>

  <transmission name="trans9">
    <type>transmission_interface/SimpleTransmission</type>
    <actuator name="motor9">
      <mechanicalReduction>100</mechanicalReduction>
    </actuator>
    <joint name="joint9">
      <hardwareInterface>EffortJointInterface</hardwareInterface>
    </joint>
  </transmission>

  <transmission name="trans10">
    <type>transmission_interface/SimpleTransmission</type>
    <actuator name="motor10">
      <mechanicalReduction>100</mechanicalReduction>
    </actuator>
    <joint name="joint10">
      <hardwareInterface>EffortJointInterface</hardwareInterface>
    </joint>
  </transmission>

  <transmission name="trans11">
    <type>transmission_interface/SimpleTransmission</type>
    <actuator name="motor11">
      <mechanicalReduction>100</mechanicalReduction>
    </actuator>
    <joint name="joint11">
      <hardwareInterface>EffortJointInterface</hardwareInterface>
    </joint>
  </transmission>

  <transmission name="trans12">
    <type>transmission_interface/SimpleTransmission</type>
    <actuator name="motor12">
      <mechanicalReduction>100</mechanicalReduction>
    </actuator>
    <joint name="joint12">
      <hardwareInterface>EffortJointInterface</hardwareInterface>
    </joint>
  </transmission>

    <transmission name="trans13">
    <type>transmission_interface/SimpleTransmission</type>
    <actuator name="motor13">
      <mechanicalReduction>100</mechanicalReduction>
    </actuator>
    <joint name="joint13">
      <hardwareInterface>EffortJointInterface</hardwareInterface>
    </joint>
  </transmission>

  <transmission name="trans14">
    <type>transmission_interface/SimpleTransmission</type>
    <actuator name="motor14">
      <mechanicalReduction>100</mechanicalReduction>
    </actuator>
    <joint name="joint14">
      <hardwareInterface>EffortJointInterface</hardwareInterface>
    </joint>
  </transmission>

  <transmission name="trans15">
    <type>transmission_interface/SimpleTransmission</type>
    <actuator name="motor15">
      <mechanicalReduction>100</mechanicalReduction>
    </actuator>
    <joint name="joint15">
      <hardwareInterface>EffortJointInterface</hardwareInterface>
    </joint>
  </transmission>



</robot>