<?xml version="1.0" ?>
<robot name="snake_robot" >


  <material name="blue">
    <color rgba="0.3765 0.5647 0.101 1"/>
  </material>

  <material name="gray">
    <color rgba="0.0 0.0 0.0 1"/>
  </material>

  <link name="base_link">
    <inertial>
      <origin xyz=" 0 0 0" rpy="0 0 0" />
      <mass value="1.0"/>
      <inertia ixx="0.1" ixy="0.0" ixz="0.0" iyy="0.1" iyz="0.0" izz="0.1"/>
    </inertial>
    <visual>
      <geometry>
        <cylinder length="0.5" radius="0.05"/>
      </geometry>
      <material name="blue"/>
    </visual>
    <collision>
      <geometry>
        <cylinder length="0.5" radius="0.05"/>
      </geometry>
    </collision>

  <gazebo reference="base_link">
    <material>Gazebo/Orange</material>
  </gazebo>
  
  </link>

  <link name="link2">
    <visual>
      <geometry>
        <cylinder length="0.5" radius="0.05"/>
      </geometry>
      <origin xyz=" 0 0 0.25" rpy = "0 0 0" />
      <material name="gray"/>
    </visual>
    <inertial>
      <origin xyz=" 0 0 0" rpy="0 0 0" />
      <mass value="1.0"/>
      <inertia ixx="0.1" ixy="0.0" ixz="0.0" iyy="0.1" iyz="0.0" izz="0.1"/>
    </inertial>
    <collision>
      <geometry>
        <cylinder length="0.5" radius="0.05"/>
      </geometry>
    </collision>

  <gazebo reference="link2">
    <material>Gazebo/Green</material>
  </gazebo>
  </link>

  <link name="link3">
    <visual>
      <geometry>
        <cylinder length="0.5" radius="0.05"/>
      </geometry>
      <material name="blue"/>
      <origin xyz=" 0 0 0.25" rpy = "0 0 0" />
    </visual>
    <inertial>
      <origin xyz=" 0 0 0" rpy="0 0 0" />
      <mass value="1.0"/>
      <inertia ixx="0.1" ixy="0.0" ixz="0.0" iyy="0.1" iyz="0.0" izz="0.1"/>
    </inertial>
    <collision>
      <geometry>
        <cylinder length="0.5" radius="0.05"/>
      </geometry>
    </collision>
  </link>

  <link name="link4">
    <visual>
      <geometry>
        <cylinder length="0.5" radius="0.05"/>
      </geometry>
    <material name="gray"/>
    <origin xyz=" 0 0 0.25" rpy = "0 0 0" />
    </visual>
    <inertial>
      <origin xyz=" 0 0 0" rpy="0 0 0" />
      <mass value="1.0"/>
      <inertia ixx="0.1" ixy="0.0" ixz="0.0" iyy="0.1" iyz="0.0" izz="0.1"/>
    </inertial>
    <collision>
      <geometry>
        <cylinder length="0.5" radius="0.05"/>
      </geometry>
    </collision>
  </link>

  <link name="link5">
    <visual>
      <geometry>
        <cylinder length="0.5" radius="0.05"/>
      </geometry>
      <material name="blue"/>
      <origin xyz=" 0 0 0.25" rpy = "0 0 0" />
    </visual>
    <inertial>
      <origin xyz=" 0 0 0" rpy="0 0 0" />
      <mass value="1.0"/>
      <inertia ixx="0.1" ixy="0.0" ixz="0.0" iyy="0.1" iyz="0.0" izz="0.1"/>
    </inertial>
    <collision>
      <geometry>
        <cylinder length="0.5" radius="0.05"/>
      </geometry>
    </collision>
  </link>

    <link name="link6">
    <visual>
      <geometry>
        <cylinder length="0.5" radius="0.05"/>
      </geometry>
      <material name="gray"/>
      <origin xyz=" 0 0 0.25" rpy = "0 0 0" />
    </visual>
    <inertial>
      <origin xyz=" 0 0 0" rpy="0 0 0" />
      <mass value="1.0"/>
      <inertia ixx="0.1" ixy="0.0" ixz="0.0" iyy="0.1" iyz="0.0" izz="0.1"/>
    </inertial>
    <collision>
      <geometry>
        <cylinder length="0.5" radius="0.05"/>
      </geometry>
    </collision>
  </link>

  <link name="link7">
    <visual>
      <geometry>
        <cylinder length="0.5" radius="0.05"/>
      </geometry>
      <material name="blue"/>
      <origin xyz=" 0 0 0.25" rpy = "0 0 0" />
    </visual>
    <inertial>
      <origin xyz=" 0 0 0" rpy="0 0 0" />
      <mass value="1.0"/>
      <inertia ixx="0.1" ixy="0.0" ixz="0.0" iyy="0.1" iyz="0.0" izz="0.1"/>
    </inertial>
    <collision>
      <geometry>
        <cylinder length="0.5" radius="0.05"/>
      </geometry>
    </collision>
  </link>

  <link name="link8">
    <visual>
      <geometry>
        <cylinder length="0.5" radius="0.05"/>
      </geometry>
      <material name="gray"/>
      <origin xyz=" 0 0 0.25" rpy = "0 0 0" />
    </visual>
    <inertial>
      <origin xyz=" 0 0 0" rpy="0 0 0" />
      <mass value="1.0"/>
      <inertia ixx="0.1" ixy="0.0" ixz="0.0" iyy="0.1" iyz="0.0" izz="0.1"/>
    </inertial>
    <collision>
      <geometry>
        <cylinder length="0.5" radius="0.05"/>
      </geometry>
    </collision>
  </link>
  
  <link name="link9">
    <visual>
      <geometry>
        <cylinder length="0.5" radius="0.05"/>
      </geometry>
      <material name="blue"/>
      <origin xyz=" 0 0 0.25" rpy = "0 0 0" />
    </visual>
    <inertial>
      <origin xyz=" 0 0 0" rpy="0 0 0" />
      <mass value="1.0"/>
      <inertia ixx="0.1" ixy="0.0" ixz="0.0" iyy="0.1" iyz="0.0" izz="0.1"/>
    </inertial>
    <collision>
      <geometry>
        <cylinder length="0.5" radius="0.05"/>
      </geometry>
    </collision>
  </link>

  <link name="link10">
    <visual>
      <geometry>
        <cylinder length="0.5" radius="0.05"/>
      </geometry>
      <material name="gray"/>
      <origin xyz=" 0 0 0.25" rpy = "0 0 0" />
    </visual>
    <inertial>
      <origin xyz=" 0 0 0" rpy="0 0 0" />
      <mass value="1.0"/>
      <inertia ixx="0.1" ixy="0.0" ixz="0.0" iyy="0.1" iyz="0.0" izz="0.1"/>
    </inertial>
    <collision>
      <geometry>
        <cylinder length="0.5" radius="0.05"/>
      </geometry>
    </collision>
  </link>

  <joint name="joint1" type="continuous">
    <parent link="base_link"/>
    <child link="link2"/>
    <origin xyz=" 0 0 0.25" rpy = "0 0 0" />
    <axis xyz="1 0 0" />
  </joint>

  <joint name="joint2" type="continuous">
    <parent link="link2"/>
    <child link="link3"/>
    <origin xyz=" 0 0 0.5" rpy = "0 0 0" />
    <axis xyz="0 1 0" />
  </joint>

  <joint name="joint3" type="continuous">
    <parent link="link3"/>
    <child link="link4"/>
    <origin xyz=" 0 0 0.5" rpy = "0 0 0" />
    <axis xyz="1 0 0" />
  </joint>
  
  <joint name="joint4" type="continuous">
    <parent link="link4"/>
    <child link="link5"/>
    <origin xyz=" 0 0 0.5" rpy = "0 0 0" />
    <axis xyz="0 1 0" />
  </joint>
  
  <joint name="joint5" type="continuous">
    <parent link="link5"/>
    <child link="link6"/>
    <origin xyz=" 0 0 0.5" rpy = "0 0 0" />
    <axis xyz="1 0 0" />
  </joint>

  <joint name="joint6" type="continuous">
    <parent link="link6"/>
    <child link="link7"/>
    <origin xyz=" 0 0 0.5" rpy = "0 0 0" />
    <axis xyz="0 1 0" />
  </joint>
  
  <joint name="joint7" type="continuous">
    <parent link="link7"/>
    <child link="link8"/>
    <origin xyz=" 0 0 0.5" rpy = "0 0 0" />
    <axis xyz="1 0 0" />
  </joint>

  <joint name="joint8" type="continuous">
    <parent link="link8"/>
    <child link="link9"/>
    <origin xyz=" 0 0 0.5" rpy = "0 0 0" />
    <axis xyz="1 0 0" />
  </joint>

  <joint name="joint9" type="continuous">
    <parent link="link9"/>
    <child link="link10"/>
    <origin xyz=" 0 0 0.5" rpy = "0 0 0" />
    <axis xyz="1 0 0" />
  </joint>


<!--  NOW WE INCLUDE CONTROLS FOR ROS -->
  <gazebo>
    <plugin name="gazebo_ros_control" filename="libgazebo_ros_control.so">
      <robotNamespace>/snake_robot</robotNamespace>
    </plugin>
  </gazebo> 

  <!-- transmission -->
  <transmission name="base_to_second_trans">
    <type>transmission_interface/SimpleTransmission</type>
    <actuator name="motor1">
      <nechanicalReduction>1</nechanicalReduction>
    </actuator>
    <joint name="joint1">
      <hardwareInterface>EffortJointInterface</hardwareInterface>
    </joint>
  </transmission>

  <transmission name="second_to_third_trans">
    <type>transmission_interface/SimpleTransmission</type>
    <actuator name="motor2">
      <nechanicalReduction>1</nechanicalReduction>
    </actuator>
    <joint name="joint2">
      <hardwareInterface>EffortJointInterface</hardwareInterface>
    </joint>
  </transmission>



  <transmission name="third_to_fourth_trans">
    <type>transmission_interface/SimpleTransmission</type>
    <actuator name="motor3">
      <nechanicalReduction>1</nechanicalReduction>
    </actuator>
    <joint name="joint3">
      <hardwareInterface>EffortJointInterface</hardwareInterface>
    </joint>
  </transmission>

  <transmission name="fourth_to_fifth_trans">
    <type>transmission_interface/SimpleTransmission</type>
    <actuator name="motor4">
      <nechanicalReduction>1</nechanicalReduction>
    </actuator>
    <joint name="joint4">
      <hardwareInterface>EffortJointInterface</hardwareInterface>
    </joint>
  </transmission>

  <transmission name="fifth_to_sixth_trans">
    <type>transmission_interface/SimpleTransmission</type>
    <actuator name="motor5">
      <nechanicalReduction>1</nechanicalReduction>
    </actuator>
    <joint name="joint5">
      <hardwareInterface>EffortJointInterface</hardwareInterface>
    </joint>
  </transmission>
  
  <transmission name="sixth_to_seventh_trans">
    <type>transmission_interface/SimpleTransmission</type>
    <actuator name="motor6">
      <nechanicalReduction>1</nechanicalReduction>
    </actuator>
    <joint name="joint6">
      <hardwareInterface>EffortJointInterface</hardwareInterface>
    </joint>
  </transmission>


  <transmission name="seventh_to_eight_trans">
    <type>transmission_interface/SimpleTransmission</type>
    <actuator name="motor7">
      <nechanicalReduction>1</nechanicalReduction>
    </actuator>
    <joint name="joint7">
      <hardwareInterface>EffortJointInterface</hardwareInterface>
    </joint>
  </transmission>

  <transmission name="eigth_to_nineth_trans">
    <type>transmission_interface/SimpleTransmission</type>
    <actuator name="motor8">
      <nechanicalReduction>1</nechanicalReduction>
    </actuator>
    <joint name="joint8">
      <hardwareInterface>EffortJointInterface</hardwareInterface>
    </joint>
  </transmission>

  <transmission name="nineth_to_tenth_trans">
    <type>transmission_interface/SimpleTransmission</type>
    <actuator name="motor9">
      <nechanicalReduction>1</nechanicalReduction>
    </actuator>
    <joint name="joint9">
      <hardwareInterface>EffortJointInterface</hardwareInterface>
    </joint>
  </transmission>


</robot>